2025-02-13 18:39:38 - scripts.facebook - ERROR - Your album id is invalid, check your configs
NoneType: None
2025-02-14 01:36:28 - scripts.facebook - ERROR - Your is seted but it is not a valid album id
NoneType: None
2025-02-14 02:57:46 - scripts.facebook - ERROR - Your is seted but it is not a valid album id
NoneType: None
2025-02-15 03:56:10 - scripts.facebook - ERROR - Erro inesperado ao realizar postagem: The read operation timed out
Traceback (most recent call last):
  File "/opt/hostedtoolcache/Python/3.13.2/x64/lib/python3.13/site-packages/httpx/_transports/default.py", line 101, in map_httpcore_exceptions
    yield
  File "/opt/hostedtoolcache/Python/3.13.2/x64/lib/python3.13/site-packages/httpx/_transports/default.py", line 250, in handle_request
    resp = self._pool.handle_request(req)
  File "/opt/hostedtoolcache/Python/3.13.2/x64/lib/python3.13/site-packages/httpcore/_sync/connection_pool.py", line 256, in handle_request
    raise exc from None
  File "/opt/hostedtoolcache/Python/3.13.2/x64/lib/python3.13/site-packages/httpcore/_sync/connection_pool.py", line 236, in handle_request
    response = connection.handle_request(
        pool_request.request
    )
  File "/opt/hostedtoolcache/Python/3.13.2/x64/lib/python3.13/site-packages/httpcore/_sync/connection.py", line 103, in handle_request
    return self._connection.handle_request(request)
           ~~~~~~~~~~~~~~~~~~~~~~~~~~~~~~~^^^^^^^^^
  File "/opt/hostedtoolcache/Python/3.13.2/x64/lib/python3.13/site-packages/httpcore/_sync/http11.py", line 136, in handle_request
    raise exc
  File "/opt/hostedtoolcache/Python/3.13.2/x64/lib/python3.13/site-packages/httpcore/_sync/http11.py", line 106, in handle_request
    ) = self._receive_response_headers(**kwargs)
        ~~~~~~~~~~~~~~~~~~~~~~~~~~~~~~^^^^^^^^^^
  File "/opt/hostedtoolcache/Python/3.13.2/x64/lib/python3.13/site-packages/httpcore/_sync/http11.py", line 177, in _receive_response_headers
    event = self._receive_event(timeout=timeout)
  File "/opt/hostedtoolcache/Python/3.13.2/x64/lib/python3.13/site-packages/httpcore/_sync/http11.py", line 217, in _receive_event
    data = self._network_stream.read(
        self.READ_NUM_BYTES, timeout=timeout
    )
  File "/opt/hostedtoolcache/Python/3.13.2/x64/lib/python3.13/site-packages/httpcore/_backends/sync.py", line 126, in read
    with map_exceptions(exc_map):
         ~~~~~~~~~~~~~~^^^^^^^^^
  File "/opt/hostedtoolcache/Python/3.13.2/x64/lib/python3.13/contextlib.py", line 162, in __exit__
    self.gen.throw(value)
    ~~~~~~~~~~~~~~^^^^^^^
  File "/opt/hostedtoolcache/Python/3.13.2/x64/lib/python3.13/site-packages/httpcore/_exceptions.py", line 14, in map_exceptions
    raise to_exc(exc) from exc
httpcore.ReadTimeout: The read operation timed out

The above exception was the direct cause of the following exception:

Traceback (most recent call last):
  File "/home/runner/work/EFIO-PYTHON/EFIO-PYTHON/scripts/facebook.py", line 95, in fb_posting
    response = httpx.post(endpoint, data=data, files=files, timeout=15)
  File "/opt/hostedtoolcache/Python/3.13.2/x64/lib/python3.13/site-packages/httpx/_api.py", line 304, in post
    return request(
        "POST",
    ...<13 lines>...
        trust_env=trust_env,
    )
  File "/opt/hostedtoolcache/Python/3.13.2/x64/lib/python3.13/site-packages/httpx/_api.py", line 109, in request
    return client.request(
           ~~~~~~~~~~~~~~^
        method=method,
        ^^^^^^^^^^^^^^
    ...<8 lines>...
        follow_redirects=follow_redirects,
        ^^^^^^^^^^^^^^^^^^^^^^^^^^^^^^^^^^
    )
    ^
  File "/opt/hostedtoolcache/Python/3.13.2/x64/lib/python3.13/site-packages/httpx/_client.py", line 825, in request
    return self.send(request, auth=auth, follow_redirects=follow_redirects)
           ~~~~~~~~~^^^^^^^^^^^^^^^^^^^^^^^^^^^^^^^^^^^^^^^^^^^^^^^^^^^^^^^
  File "/opt/hostedtoolcache/Python/3.13.2/x64/lib/python3.13/site-packages/httpx/_client.py", line 914, in send
    response = self._send_handling_auth(
        request,
    ...<2 lines>...
        history=[],
    )
  File "/opt/hostedtoolcache/Python/3.13.2/x64/lib/python3.13/site-packages/httpx/_client.py", line 942, in _send_handling_auth
    response = self._send_handling_redirects(
        request,
        follow_redirects=follow_redirects,
        history=history,
    )
  File "/opt/hostedtoolcache/Python/3.13.2/x64/lib/python3.13/site-packages/httpx/_client.py", line 979, in _send_handling_redirects
    response = self._send_single_request(request)
  File "/opt/hostedtoolcache/Python/3.13.2/x64/lib/python3.13/site-packages/httpx/_client.py", line 1014, in _send_single_request
    response = transport.handle_request(request)
  File "/opt/hostedtoolcache/Python/3.13.2/x64/lib/python3.13/site-packages/httpx/_transports/default.py", line 249, in handle_request
    with map_httpcore_exceptions():
         ~~~~~~~~~~~~~~~~~~~~~~~^^
  File "/opt/hostedtoolcache/Python/3.13.2/x64/lib/python3.13/contextlib.py", line 162, in __exit__
    self.gen.throw(value)
    ~~~~~~~~~~~~~~^^^^^^^
  File "/opt/hostedtoolcache/Python/3.13.2/x64/lib/python3.13/site-packages/httpx/_transports/default.py", line 118, in map_httpcore_exceptions
    raise mapped_exc(message) from exc
httpx.ReadTimeout: The read operation timed out
2025-02-15 03:56:10 - scripts.facebook - ERROR - Erro ao executar fb_posting (tentativa 1/3): The read operation timed out
Traceback (most recent call last):
  File "/opt/hostedtoolcache/Python/3.13.2/x64/lib/python3.13/site-packages/httpx/_transports/default.py", line 101, in map_httpcore_exceptions
    yield
  File "/opt/hostedtoolcache/Python/3.13.2/x64/lib/python3.13/site-packages/httpx/_transports/default.py", line 250, in handle_request
    resp = self._pool.handle_request(req)
  File "/opt/hostedtoolcache/Python/3.13.2/x64/lib/python3.13/site-packages/httpcore/_sync/connection_pool.py", line 256, in handle_request
    raise exc from None
  File "/opt/hostedtoolcache/Python/3.13.2/x64/lib/python3.13/site-packages/httpcore/_sync/connection_pool.py", line 236, in handle_request
    response = connection.handle_request(
        pool_request.request
    )
  File "/opt/hostedtoolcache/Python/3.13.2/x64/lib/python3.13/site-packages/httpcore/_sync/connection.py", line 103, in handle_request
    return self._connection.handle_request(request)
           ~~~~~~~~~~~~~~~~~~~~~~~~~~~~~~~^^^^^^^^^
  File "/opt/hostedtoolcache/Python/3.13.2/x64/lib/python3.13/site-packages/httpcore/_sync/http11.py", line 136, in handle_request
    raise exc
  File "/opt/hostedtoolcache/Python/3.13.2/x64/lib/python3.13/site-packages/httpcore/_sync/http11.py", line 106, in handle_request
    ) = self._receive_response_headers(**kwargs)
        ~~~~~~~~~~~~~~~~~~~~~~~~~~~~~~^^^^^^^^^^
  File "/opt/hostedtoolcache/Python/3.13.2/x64/lib/python3.13/site-packages/httpcore/_sync/http11.py", line 177, in _receive_response_headers
    event = self._receive_event(timeout=timeout)
  File "/opt/hostedtoolcache/Python/3.13.2/x64/lib/python3.13/site-packages/httpcore/_sync/http11.py", line 217, in _receive_event
    data = self._network_stream.read(
        self.READ_NUM_BYTES, timeout=timeout
    )
  File "/opt/hostedtoolcache/Python/3.13.2/x64/lib/python3.13/site-packages/httpcore/_backends/sync.py", line 126, in read
    with map_exceptions(exc_map):
         ~~~~~~~~~~~~~~^^^^^^^^^
  File "/opt/hostedtoolcache/Python/3.13.2/x64/lib/python3.13/contextlib.py", line 162, in __exit__
    self.gen.throw(value)
    ~~~~~~~~~~~~~~^^^^^^^
  File "/opt/hostedtoolcache/Python/3.13.2/x64/lib/python3.13/site-packages/httpcore/_exceptions.py", line 14, in map_exceptions
    raise to_exc(exc) from exc
httpcore.ReadTimeout: The read operation timed out

The above exception was the direct cause of the following exception:

Traceback (most recent call last):
  File "/home/runner/work/EFIO-PYTHON/EFIO-PYTHON/scripts/facebook.py", line 21, in wrapper
    return func(*args, **kwargs)
  File "/home/runner/work/EFIO-PYTHON/EFIO-PYTHON/scripts/facebook.py", line 95, in fb_posting
    response = httpx.post(endpoint, data=data, files=files, timeout=15)
  File "/opt/hostedtoolcache/Python/3.13.2/x64/lib/python3.13/site-packages/httpx/_api.py", line 304, in post
    return request(
        "POST",
    ...<13 lines>...
        trust_env=trust_env,
    )
  File "/opt/hostedtoolcache/Python/3.13.2/x64/lib/python3.13/site-packages/httpx/_api.py", line 109, in request
    return client.request(
           ~~~~~~~~~~~~~~^
        method=method,
        ^^^^^^^^^^^^^^
    ...<8 lines>...
        follow_redirects=follow_redirects,
        ^^^^^^^^^^^^^^^^^^^^^^^^^^^^^^^^^^
    )
    ^
  File "/opt/hostedtoolcache/Python/3.13.2/x64/lib/python3.13/site-packages/httpx/_client.py", line 825, in request
    return self.send(request, auth=auth, follow_redirects=follow_redirects)
           ~~~~~~~~~^^^^^^^^^^^^^^^^^^^^^^^^^^^^^^^^^^^^^^^^^^^^^^^^^^^^^^^
  File "/opt/hostedtoolcache/Python/3.13.2/x64/lib/python3.13/site-packages/httpx/_client.py", line 914, in send
    response = self._send_handling_auth(
        request,
    ...<2 lines>...
        history=[],
    )
  File "/opt/hostedtoolcache/Python/3.13.2/x64/lib/python3.13/site-packages/httpx/_client.py", line 942, in _send_handling_auth
    response = self._send_handling_redirects(
        request,
        follow_redirects=follow_redirects,
        history=history,
    )
  File "/opt/hostedtoolcache/Python/3.13.2/x64/lib/python3.13/site-packages/httpx/_client.py", line 979, in _send_handling_redirects
    response = self._send_single_request(request)
  File "/opt/hostedtoolcache/Python/3.13.2/x64/lib/python3.13/site-packages/httpx/_client.py", line 1014, in _send_single_request
    response = transport.handle_request(request)
  File "/opt/hostedtoolcache/Python/3.13.2/x64/lib/python3.13/site-packages/httpx/_transports/default.py", line 249, in handle_request
    with map_httpcore_exceptions():
         ~~~~~~~~~~~~~~~~~~~~~~~^^
  File "/opt/hostedtoolcache/Python/3.13.2/x64/lib/python3.13/contextlib.py", line 162, in __exit__
    self.gen.throw(value)
    ~~~~~~~~~~~~~~^^^^^^^
  File "/opt/hostedtoolcache/Python/3.13.2/x64/lib/python3.13/site-packages/httpx/_transports/default.py", line 118, in map_httpcore_exceptions
    raise mapped_exc(message) from exc
httpx.ReadTimeout: The read operation timed out
